2021/01/27 18:35:37 Attempt 1 of http call to http://10.0.0.5:16384/sendlogstoartifacts/info
2021/01/27 18:35:37 Http request failed with status: 500
Response body: Unable to write to log.


2021/01/27 18:35:37 Response code 500, retrying after 1 seconds
2021/01/27 18:35:38 Attempt 2 of http call to http://10.0.0.5:16384/sendlogstoartifacts/info
2021/01/27 18:35:38 Http request failed with status: 500
Response body: Unable to write to log.


2021/01/27 18:35:38 Response code 500, retrying after 2 seconds
[2021-01-27T18:35:39.318331] Entering context manager injector.
2021/01/27 18:35:40 Attempt 3 of http call to http://10.0.0.5:16384/sendlogstoartifacts/info
[context_manager_injector.py] Command line Options: Namespace(inject=['ProjectPythonPath:context_managers.ProjectPythonPath', 'RunHistory:context_managers.RunHistory', 'TrackUserError:context_managers.TrackUserError'], invocation=['train.py', '--C', '0.3785552196251123', '--max_iter', '100'])
2021/01/27 18:35:40 Attempt 1 of http call to http://10.0.0.5:16384/sendlogstoartifacts/status
Script type = None
Starting the daemon thread to refresh tokens in background for process with pid = 98
Entering Run History Context Manager.
[2021-01-27T18:35:42.620650] Current directory: /mnt/batch/tasks/shared/LS_root/jobs/quick-starts-ws-136297/azureml/hd_faf9701f-f3f6-46b0-b4bd-b64d889c6c29_4/mounts/workspaceblobstore/azureml/HD_faf9701f-f3f6-46b0-b4bd-b64d889c6c29_4
[2021-01-27T18:35:42.620780] Preparing to call script [train.py] with arguments:['--C', '0.3785552196251123', '--max_iter', '100']
[2021-01-27T18:35:42.620842] After variable expansion, calling script [train.py] with arguments:['--C', '0.3785552196251123', '--max_iter', '100']

Performing interactive authentication. Please follow the instructions on the terminal.
To sign in, use a web browser to open the page https://microsoft.com/devicelogin and enter the code FR62VGSS2 to authenticate.
You have logged in. Now let us find all the subscriptions to which you have access...
Interactive authentication successfully completed.
Starting the daemon thread to refresh tokens in background for process with pid = 98


[2021-01-27T18:41:26.198894] The experiment failed. Finalizing run...
Cleaning up all outstanding Run operations, waiting 900.0 seconds
1 items cleaning up...
Cleanup took 0.06494522094726562 seconds
Starting the daemon thread to refresh tokens in background for process with pid = 98
Traceback (most recent call last):
  File "/azureml-envs/azureml_ba9520bf386d662001eeb9523395794e/lib/python3.6/site-packages/azureml/_project/_commands.py", line 387, in get_workspace
    workspace_name)
  File "/azureml-envs/azureml_ba9520bf386d662001eeb9523395794e/lib/python3.6/site-packages/azureml/_base_sdk_common/workspace/operations/workspaces_operations.py", line 87, in get
    raise models.ErrorResponseWrapperException(self._deserialize, response)
azureml._base_sdk_common.workspace.models.error_response_wrapper.ErrorResponseWrapperException: Operation returned an invalid status code 'Forbidden'

During handling of the above exception, another exception occurred:

Traceback (most recent call last):
  File "/mnt/batch/tasks/shared/LS_root/jobs/quick-starts-ws-136297/azureml/hd_faf9701f-f3f6-46b0-b4bd-b64d889c6c29_4/mounts/workspaceblobstore/azureml/HD_faf9701f-f3f6-46b0-b4bd-b64d889c6c29_4/azureml-setup/context_manager_injector.py", line 210, in execute_with_context
    runpy.run_path(sys.argv[0], globals(), run_name="__main__")
  File "/azureml-envs/azureml_ba9520bf386d662001eeb9523395794e/lib/python3.6/runpy.py", line 263, in run_path
    pkg_name=pkg_name, script_name=fname)
  File "/azureml-envs/azureml_ba9520bf386d662001eeb9523395794e/lib/python3.6/runpy.py", line 96, in _run_module_code
    mod_name, mod_spec, pkg_name, script_name)
  File "/azureml-envs/azureml_ba9520bf386d662001eeb9523395794e/lib/python3.6/runpy.py", line 85, in _run_code
    exec(code, run_globals)
  File "train.py", line 89, in <module>
    main()
  File "train.py", line 65, in main
    workspace = Workspace(subscription_id, resource_group, workspace_name)
  File "/azureml-envs/azureml_ba9520bf386d662001eeb9523395794e/lib/python3.6/site-packages/azureml/core/workspace.py", line 205, in __init__
    auth, subscription_id, resource_group, workspace_name)
  File "/azureml-envs/azureml_ba9520bf386d662001eeb9523395794e/lib/python3.6/site-packages/azureml/_project/_commands.py", line 393, in get_workspace
    resource_error_handling(response_exception, WORKSPACE)
  File "/azureml-envs/azureml_ba9520bf386d662001eeb9523395794e/lib/python3.6/site-packages/azureml/_base_sdk_common/common.py", line 334, in resource_error_handling
    raise ProjectSystemException(response_message)
azureml.exceptions._azureml_exception.ProjectSystemException: ProjectSystemException:
	Message: {
    "error_details": {
        "error": {
            "code": "AuthorizationFailed",
            "message": "The client 'odl_user_136297@udacitylabs.onmicrosoft.com' with object id '0ac25477-b6bd-4c7e-81c9-b537d6f7eef1' does not have authorization to perform action 'Microsoft.MachineLearningServices/workspaces/read' over scope '/subscriptions/610d6e37-4747-4a20-80eb-3aad70a55f43/resourceGroups/ aml-quickstarts-136297/providers/Microsoft.MachineLearningServices/workspaces/quick-starts-ws-136297' or the scope is invalid. If access was recently granted, please refresh your credentials."
        }
    },
    "status_code": 403,
    "url": "https://management.azure.com/subscriptions/610d6e37-4747-4a20-80eb-3aad70a55f43/resourceGroups/%20aml-quickstarts-136297/providers/Microsoft.MachineLearningServices/workspaces/quick-starts-ws-136297?api-version=2020-01-01"
}
	InnerException None
	ErrorResponse 
{
    "error": {
        "message": "{\n    \"error_details\": {\n        \"error\": {\n            \"code\": \"AuthorizationFailed\",\n            \"message\": \"The client 'odl_user_136297@udacitylabs.onmicrosoft.com' with object id '0ac25477-b6bd-4c7e-81c9-b537d6f7eef1' does not have authorization to perform action 'Microsoft.MachineLearningServices/workspaces/read' over scope '/subscriptions/610d6e37-4747-4a20-80eb-3aad70a55f43/resourceGroups/ aml-quickstarts-136297/providers/Microsoft.MachineLearningServices/workspaces/quick-starts-ws-136297' or the scope is invalid. If access was recently granted, please refresh your credentials.\"\n        }\n    },\n    \"status_code\": 403,\n    \"url\": \"https://management.azure.com/subscriptions/610d6e37-4747-4a20-80eb-3aad70a55f43/resourceGroups/%20aml-quickstarts-136297/providers/Microsoft.MachineLearningServices/workspaces/quick-starts-ws-136297?api-version=2020-01-01\"\n}"
    }
}

During handling of the above exception, another exception occurred:

Traceback (most recent call last):
  File "train.py", line 89, in <module>
    main()
  File "train.py", line 65, in main
    workspace = Workspace(subscription_id, resource_group, workspace_name)
  File "/azureml-envs/azureml_ba9520bf386d662001eeb9523395794e/lib/python3.6/site-packages/azureml/core/workspace.py", line 205, in __init__
    auth, subscription_id, resource_group, workspace_name)
  File "/azureml-envs/azureml_ba9520bf386d662001eeb9523395794e/lib/python3.6/site-packages/azureml/_project/_commands.py", line 393, in get_workspace
    resource_error_handling(response_exception, WORKSPACE)
  File "/azureml-envs/azureml_ba9520bf386d662001eeb9523395794e/lib/python3.6/site-packages/azureml/_base_sdk_common/common.py", line 334, in resource_error_handling
    raise ProjectSystemException(response_message)
UserScriptException: UserScriptException:
	Message: {
    "error_details": {
        "error": {
            "code": "AuthorizationFailed",
            "message": "The client 'odl_user_136297@udacitylabs.onmicrosoft.com' with object id '0ac25477-b6bd-4c7e-81c9-b537d6f7eef1' does not have authorization to perform action 'Microsoft.MachineLearningServices/workspaces/read' over scope '/subscriptions/610d6e37-4747-4a20-80eb-3aad70a55f43/resourceGroups/ aml-quickstarts-136297/providers/Microsoft.MachineLearningServices/workspaces/quick-starts-ws-136297' or the scope is invalid. If access was recently granted, please refresh your credentials."
        }
    },
    "status_code": 403,
    "url": "https://management.azure.com/subscriptions/610d6e37-4747-4a20-80eb-3aad70a55f43/resourceGroups/%20aml-quickstarts-136297/providers/Microsoft.MachineLearningServices/workspaces/quick-starts-ws-136297?api-version=2020-01-01"
}
	InnerException ProjectSystemException:
	Message: {
    "error_details": {
        "error": {
            "code": "AuthorizationFailed",
            "message": "The client 'odl_user_136297@udacitylabs.onmicrosoft.com' with object id '0ac25477-b6bd-4c7e-81c9-b537d6f7eef1' does not have authorization to perform action 'Microsoft.MachineLearningServices/workspaces/read' over scope '/subscriptions/610d6e37-4747-4a20-80eb-3aad70a55f43/resourceGroups/ aml-quickstarts-136297/providers/Microsoft.MachineLearningServices/workspaces/quick-starts-ws-136297' or the scope is invalid. If access was recently granted, please refresh your credentials."
        }
    },
    "status_code": 403,
    "url": "https://management.azure.com/subscriptions/610d6e37-4747-4a20-80eb-3aad70a55f43/resourceGroups/%20aml-quickstarts-136297/providers/Microsoft.MachineLearningServices/workspaces/quick-starts-ws-136297?api-version=2020-01-01"
}
	InnerException None
	ErrorResponse 
{
    "error": {
        "message": "{\n    \"error_details\": {\n        \"error\": {\n            \"code\": \"AuthorizationFailed\",\n            \"message\": \"The client 'odl_user_136297@udacitylabs.onmicrosoft.com' with object id '0ac25477-b6bd-4c7e-81c9-b537d6f7eef1' does not have authorization to perform action 'Microsoft.MachineLearningServices/workspaces/read' over scope '/subscriptions/610d6e37-4747-4a20-80eb-3aad70a55f43/resourceGroups/ aml-quickstarts-136297/providers/Microsoft.MachineLearningServices/workspaces/quick-starts-ws-136297' or the scope is invalid. If access was recently granted, please refresh your credentials.\"\n        }\n    },\n    \"status_code\": 403,\n    \"url\": \"https://management.azure.com/subscriptions/610d6e37-4747-4a20-80eb-3aad70a55f43/resourceGroups/%20aml-quickstarts-136297/providers/Microsoft.MachineLearningServices/workspaces/quick-starts-ws-136297?api-version=2020-01-01\"\n}"
    }
}
	ErrorResponse 
{
    "error": {
        "code": "UserError",
        "message": "{\n    \"error_details\": {\n        \"error\": {\n            \"code\": \"AuthorizationFailed\",\n            \"message\": \"The client 'odl_user_136297@udacitylabs.onmicrosoft.com' with object id '0ac25477-b6bd-4c7e-81c9-b537d6f7eef1' does not have authorization to perform action 'Microsoft.MachineLearningServices/workspaces/read' over scope '/subscriptions/610d6e37-4747-4a20-80eb-3aad70a55f43/resourceGroups/ aml-quickstarts-136297/providers/Microsoft.MachineLearningServices/workspaces/quick-starts-ws-136297' or the scope is invalid. If access was recently granted, please refresh your credentials.\"\n        }\n    },\n    \"status_code\": 403,\n    \"url\": \"https://management.azure.com/subscriptions/610d6e37-4747-4a20-80eb-3aad70a55f43/resourceGroups/%20aml-quickstarts-136297/providers/Microsoft.MachineLearningServices/workspaces/quick-starts-ws-136297?api-version=2020-01-01\"\n}"
    }
}

[2021-01-27T18:41:26.448029] Finished context manager injector with Exception.
2021/01/27 18:41:26 Failed to parse control script error: /mnt/batch/tasks/workitems/eadde85d-3f87-461c-a690-9d20a4edc93c/job-1/hd_faf9701f-f3f6-46b_769fcd5a-1069-44ec-bbc8-dcbeb9095a8a/wd/runTaskLetTask_error.json to json File /mnt/batch/tasks/workitems/eadde85d-3f87-461c-a690-9d20a4edc93c/job-1/hd_faf9701f-f3f6-46b_769fcd5a-1069-44ec-bbc8-dcbeb9095a8a/wd/runTaskLetTask_error.json doesn't exist
2021/01/27 18:41:26 Failed to run the wrapper cmd with err: exit status 1
2021/01/27 18:41:26 Attempt 1 of http call to http://10.0.0.5:16384/sendlogstoartifacts/status
2021/01/27 18:41:26 mpirun version string: {
Intel(R) MPI Library for Linux* OS, Version 2018 Update 3 Build 20180411 (id: 18329)
Copyright 2003-2018 Intel Corporation.
}
2021/01/27 18:41:26 MPI publisher: intel ; version: 2018
2021/01/27 18:41:26 Process Exiting with Code:  1
